Workbook
Name general: 'dataType Dropdown Items'!$A$3:$A$18
Name 一般: [1]dataTypeプルダウン項目!$A$3:$A$16
Name 固定フォーマット: [1]dataTypeプルダウン項目!#REF!
Name 日時: [1]dataTypeプルダウン項目!#REF!

Sheet dataType Dropdown Items
A1: dataType Definition
A2: General | B2: Type | C2: FRAMEWORK_KIND
A3: All Characters | B3: STRING | C3: Spring Framework
A4: Full-width | B4: INTEGER
A5: Half-width | B5: SHORT
A6: Half-width Numeric | B6: LONG
A7: Uppercase | B7: FLOAT
A8: Uppercase + Underscore | B8: DOUBLE
A9: Lowercase | B9: BIG_INTEGER
A10: Lowercase + Underscore | B10: BIG_DECIMAL
A11: Numeric + Uppercase | B11: YEAR_MONTH
A12: Numeric + Uppercase + Underscore | B12: DATE
A13: Numeric + Lowercase | B13: TIME
A14: Numeric + Lowercase + Underscore | B14: DATE_TIME
A15: Alphanumeric | B15: TIMESTAMP
A16: Alphanumeric + Underscore | B16: ENUM
B17: BOOLEAN
C20: ※"jakarta EE" assumued but not ready

Sheet dataType Data Pattern List
A1: Data Pattern | B1: enumValue
A2: All Characters | B2: REG_EX_ALL
A3: Half-width | B3: REG_EX_HAN
A4: Half-width Numeric | B4: REG_EX_HAN_NUM
A5: Uppercase | B5: REG_EX_HAN_UC
A6: Uppercase + Underscore | B6: REG_EX_HAN_UC_US
A7: Lowercase | B7: REG_EX_HAN_LC
A8: Lowercase + Underscore | B8: REG_EX_HAN_LC_US
A9: Numeric + Uppercase | B9: REG_EX_HAN_NUM_UC
A10: Numeric + Uppercase + Underscore | B10: REG_EX_HAN_NUM_UC_US
A11: Numeric + Lowercase | B11: REG_EX_HAN_NUM_LC
A12: Numeric + Lowercase + Underscore | B12: REG_EX_HAN_NUM_LC_US
... A15: Full-width | B15: REG_EX_ZEN

Sheet FK Types
A1: FK Type (Japanese) | B1: FK Type | C1: Direction
A2: Source 1 - Target 1 (unidirectional) | B2: OneToOne | C2: unidirectional
A3: Source 1 - Target 1 (bidirectional) | B3: OneToOne | C3: bidirectional
A4: Source N - Target 1 (unidirectional) | B4: ManyToOne | C4: unidirectional
A11: * The following are not supported by the framework due to performance concerns
A12: Source 1 - Target N (unidirectional)
A13: Source N - Target 1 / Source 1 - Target N (bidirectional)
A14: Source M - Target N (unidirectional)
A15: Source M - Target N (bidirectional)

Sheet Format Change History
A1: Format Change History
A3: Date | B3: Version | C3: Changes | D3: Changed By
A4: 46196 | B4: v5.0.0 | C4: ■Version Information - Supported code-generator version: 15.0.0-beta.4 or later ■Change Description - Added English version of the Excel template | D4: Y.Tanaka

Sheet General Settings
A1: General Settings
A3: * Fill in the "Value" and "Notes" columns only. Do not modify other columns. "Notes" is optional (no system impact).
A5: # | B5: Category | C5: Category Name | D5: Key | E5: Description | F5: Required | G5: Value | H5: Notes
A6: =ROW()-5 -> 1 | B6: SYSTEM_COMMON | C6: System Common | D6: TEMPLATE_VERSION | E6: Template version of this Excel file | F6: ◯ | G6: 5.0.0
A7: =ROW()-5 -> 2 | B7: SYSTEM_COMMON | C7: System Common | D7: SYSTEM_NAME | E7: System name * Used as the parent folder name for auto-generated source files | F7: ◯ | G7: qiita-data-viewer
A8: =ROW()-5 -> 3 | B8: SYSTEM_COMMON | C8: System Common | D8: BASE_PACKAGE | E8: Common part of the package name | F8: ◯ | G8: jp.ecuacion.app.qiitadataviewer
A9: =ROW()-5 -> 4 | B9: SYSTEM_COMMON | C9: System Common | D9: FRAMEWORK_KIND | E9: Framework type * Generated code differs depending on the specified type | F9: ◯ | G9: Spring Framework
A10: =ROW()-5 -> 5 | B10: SYSTEM_COMMON | C10: System Common | D10: CHARSET | E10: Source code character encoding ("UTF-8" recommended) | F10: ◯ | G10: UTF-8
A11: =ROW()-5 -> 6 | B11: SYSTEM_COMMON | C11: System Common | D11: LANG_DEFAULT | E11: Default language * Specify a locale string such as "en". "en_US" etc. are also supported. | F11: ◯ | G11: en
A12: =ROW()-5 -> 7 | B12: SYSTEM_COMMON | C12: System Common | D12: LANG_SUPPORT_01 | E12: Support language 1 * Enter support languages in order 1, 2, 3. Having 1 empty while 2 is filled will cause an error. | G12: ja
A13: =ROW()-5 -> 8 | B13: SYSTEM_COMMON | C13: System Common | D13: LANG_SUPPORT_02 | E13: Support language 2
A14: =ROW()-5 -> 9 | B14: SYSTEM_COMMON | C14: System Common | D14: LANG_SUPPORT_03 | E14: Support language 3
A15: =ROW()-5 -> 10 | B15: SYSTEM_COMMON | C15: System Common | D15: PROHIBITED_CHARS | E15: Prohibited characters | G15: !"#$%&()=^~\|`[{;+:*]},<>/?
A16: =ROW()-5 -> 11 | B16: SYSTEM_COMMON | C16: System Common | D16: PROHIBITED_CHARS_DESC_LANG_DEFAULT | E16: Prohibited chars pattern description (default language) * Required when "Prohibited characters" is not empty. | G16: except symbols: !"#$%&()=^~\|`[{;+:*]},<>/?
A17: =ROW()-5 -> 12 | B17: SYSTEM_COMMON | C17: System Common | D17: PROHIBITED_CHARS_DESC_LANG_SUPPORT_01 | E17: Prohibited chars pattern description (additional language 1) * Required when "Prohibited characters" and "Support language 1" are both not empty. | G17: 以下の記号以外：!"#$%&()=^~\|`[{;+:*]},<>/?
A18: =ROW()-5 -> 13 | B18: SYSTEM_COMMON | C18: System Common | D18: PROHIBITED_CHARS_DESC_LANG_SUPPORT_02 | E18: Prohibited chars pattern description (additional language 2) * Required when "Prohibited characters" and "Support language 2" are both not empty.
A19: =ROW()-5 -> 14 | B19: SYSTEM_COMMON | C19: System Common | D19: PROHIBITED_CHARS_DESC_LANG_SUPPORT_03 | E19: Prohibited chars pattern description (additional language 3) * Required when "Prohibited characters" and "Support language 3" are both not empty.
A20: =ROW()-5 -> 15 | B20: LOGICAL_DELETE | C20: Logical Delete | D20: COLUMN_NAME | E20: Column name for logical delete flag * Leave blank if not using logical delete (leave all subsequent "Logical Delete" entries blank too). * Any column with this name is treated as a logical-delete column; rename it if used for other purposes. * To use logical delete, define this column in "DB Item Definition" or "DB Common Item Definition". | G20: DEL_FLG
A21: =ROW()-5 -> 16 | B21: LOGICAL_DELETE | C21: Logical Delete | D21: DATA_TYPE_NAME | E21: DataType Name * Only BOOLEAN type DataTypes are supported in this version. | G21: DT_BOOL
A22: =ROW()-5 -> 17 | B22: LOGICAL_DELETE | C22: Logical Delete | D22: DEFAULT_VALUE | E22: Initial value (before logical delete) * Specify true/false for BOOLEAN type DataType. | G22: false
A23: =ROW()-5 -> 18 | B23: LOGICAL_DELETE | C23: Logical Delete | D23: UPDATE_VALUE | E23: Update value (after logical delete) * See "DEFAULT_VALUE" for notation. | G23: true
A24: =ROW()-5 -> 19 | B24: GROUPING | C24: Group Access Restriction Settings | D24: COLUMN_NAME | E24: Column name for group restriction * Leave blank if not using group restriction (leave all subsequent entries blank too). * Any column with this name is treated as a group column; rename it if used for other purposes. * To use this feature, define this column in "DB Item Definition" or "DB Common Item Definition". * A separate column can be designated as the group identifier via the "Group Identifier" checkbox. | G24: ACC_ID
A25: =ROW()-5 -> 20 | B25: GROUPING | C25: Group Access Restriction Settings | D25: DATA_TYPE_NAME | E25: DataType Name | G25: DT_SERIAL
A26: =ROW()-5 -> 21 | B26: GROUPING | C26: Group Access Restriction Settings | D26: TABLE_NAMES_WITHOUT_GROUPING | E26: Explicitly list tables without group settings to prevent accidental omissions. * Specify multiple tables in CSV format: "TABLE_1,TABLE_2". | G26: AGREEMENT
A27: =ROW()-5 -> 22 | B27: OPTIMISTIC_LOCKING | C27: Optimistic Locking | D27: COLUMN_NAME | E27: Column name for optimistic locking * Leave blank if not using optimistic locking (leave all subsequent entries blank too). * Any column with this name is treated as an optimistic lock column; rename it if used for other purposes. | G27: VERSION
A28: =ROW()-5 -> 23 | B28: OPTIMISTIC_LOCKING | C28: Optimistic Locking | D28: DATA_TYPE_NAME | E28: DataType Name | G28: DT_DB_UPD_VER

Sheet dataType Definition
A1: dataType Definition
P2: Default Language | Q2: Additional Language 1 | R2: Additional Language 2 | S2: Additional Language 3
A3: * DataType name prefix is fixed as "DT_" | P3: =IF('General Settings'!$G$11=0,"",'General Settings'!$G$11) -> en | Q3: =IF('General Settings'!$G$12=0,"",'General Settings'!$G$12) -> ja | R3: =IF('General Settings'!$G$13=0,"",'General Settings'!$G$13) | S3: =IF('General Settings'!$G$14=0,"",'General Settings'!$G$14)
B5: Common | C5: Input Fields for STRING | I5: Input Fields for Numeric Types | M5: For Enum | N5: For Date/Time | O5: Notes | P5: Input Fields for STRING
B6: Required | C6: Optional | D6: Required | E6: Required | F6: Required | G6: Optional | H6: Optional | I6: Optional | J6: Optional | K6: Optional | L6: Optional | M6: Required | N6: Optional | O6: Optional | P6: Optional | Q6: Optional | R6: Optional | S6: Optional
A7: DataType Name | B7: Type | C7: Min Length | D7: Max Length | E7: Data Pattern (display name) | F7: Data Pattern | G7: Exclude Prohibited Chars Check | H7: Regex | I7: Min Value | J7: Max Value | K7: Integer Digits | L7: Decimal Digits | M7: Code Length | N7: No Timezone | O7: Notes | P7: Pattern Desc (Default Lang) | Q7: Pattern Desc (Additional Lang 1) | R7: Pattern Desc (Additional Lang 2) | S7: Pattern Desc (Additional Lang 3)
A8: DT_BOOL | B8: BOOLEAN | F8: =IF(Table2[[#This Row],[Data Pattern (display name)]]="", "", VLOOKUP(Table2[[#This Row],[Data Pattern (display name)]],'dataType Data Pattern List'!A:B,2,FALSE))
A9: DT_DB_UPD_VER | B9: LONG | F9: =IF(Table2[[#This Row],[Data Pattern (display name)]]="", "", VLOOKUP(Table2[[#This Row],[Data Pattern (display name)]],'dataType Data Pattern List'!A:B,2,FALSE))
A10: DT_SERIAL | B10: LONG | F10: =IF(Table2[[#This Row],[Data Pattern (display name)]]="", "", VLOOKUP(Table2[[#This Row],[Data Pattern (display name)]],'dataType Data Pattern List'!A:B,2,FALSE))
A11: DT_TIMESTAMP | B11: DATE_TIME | F11: =IF(Table2[[#This Row],[Data Pattern (display name)]]="", "", VLOOKUP(Table2[[#This Row],[Data Pattern (display name)]],'dataType Data Pattern List'!A:B,2,FALSE))
A12: DT_CODE | B12: STRING | C12: 1 | D12: 100 | E12: Half-width | F12: =IF(Table2[[#This Row],[Data Pattern (display name)]]="", "", VLOOKUP(Table2[[#This Row],[Data Pattern (display name)]],'dataType Data Pattern List'!A:B,2,FALSE)) -> REG_EX_HAN
A13: DT_MAIL_ADDRESS | B13: STRING | C13: 1 | D13: 256 | E13: All Characters | F13: =IF(Table2[[#This Row],[Data Pattern (display name)]]="", "", VLOOKUP(Table2[[#This Row],[Data Pattern (display name)]],'dataType Data Pattern List'!A:B,2,FALSE)) -> REG_EX_ALL | G13: ○ | H13: ^[a-zA-Z0-9_\-\+\.]*@[a-zA-Z0-9_\-\.]*$ | P13: mail address format | Q13: メールアドレス形式
A14: DT_ACC_NAME | B14: STRING | C14: 1 | D14: 30 | E14: All Characters | F14: =IF(Table2[[#This Row],[Data Pattern (display name)]]="", "", VLOOKUP(Table2[[#This Row],[Data Pattern (display name)]],'dataType Data Pattern List'!A:B,2,FALSE)) -> REG_EX_ALL | H14: ^[^'$%&\(\)=\^~,<>/\?]*$ | P14: except the following symbols: '$%&()=^~,<>/? | Q14: 一部記号（'$%&()=^~,<>/?）以外
A15: DT_HASHED_PASSWORD | B15: STRING | C15: 60 | D15: 60 | E15: All Characters | F15: =IF(Table2[[#This Row],[Data Pattern (display name)]]="", "", VLOOKUP(Table2[[#This Row],[Data Pattern (display name)]],'dataType Data Pattern List'!A:B,2,FALSE)) -> REG_EX_ALL | G15: ○
A16: DT_CLOUD_NAME | B16: STRING | C16: 1 | D16: 50 | E16: All Characters | F16: =IF(Table2[[#This Row],[Data Pattern (display name)]]="", "", VLOOKUP(Table2[[#This Row],[Data Pattern (display name)]],'dataType Data Pattern List'!A:B,2,FALSE)) -> REG_EX_ALL
A17: DT_CLOUD_SERVICE_KIND | B17: ENUM | F17: =IF(Table2[[#This Row],[Data Pattern (display name)]]="", "", VLOOKUP(Table2[[#This Row],[Data Pattern (display name)]],'dataType Data Pattern List'!A:B,2,FALSE)) | M17: 2
A18: DT_CLOUD_SERVICE_SETTINGS_STRING | B18: STRING | C18: 0 | D18: 100 | E18: All Characters | F18: =IF(Table2[[#This Row],[Data Pattern (display name)]]="", "", VLOOKUP(Table2[[#This Row],[Data Pattern (display name)]],'dataType Data Pattern List'!A:B,2,FALSE)) -> REG_EX_ALL | G18: ○ | H18: ^[^'$%&\(\)=\^~,<>/\?]*$ | P18: except the following symbols: '$%&()=^~,<>/? | Q18: 一部記号（'$%&()=^~,<>/?）以外
A19: DT_SERVER_ID_IN_CLOUD_SERVICE | B19: STRING | C19: 1 | D19: 30 | E19: Half-width | F19: =IF(Table2[[#This Row],[Data Pattern (display name)]]="", "", VLOOKUP(Table2[[#This Row],[Data Pattern (display name)]],'dataType Data Pattern List'!A:B,2,FALSE)) -> REG_EX_HAN | G19: ○
A20: DT_DOMAIN | B20: STRING | D20: 100 | E20: Half-width | F20: =IF(Table2[[#This Row],[Data Pattern (display name)]]="", "", VLOOKUP(Table2[[#This Row],[Data Pattern (display name)]],'dataType Data Pattern List'!A:B,2,FALSE)) -> REG_EX_HAN | G20: ○
A21: DT_AWS_HOSTED_ZONE_ID | B21: STRING | C21: 20 | D21: 21 | E21: Half-width | F21: =IF(Table2[[#This Row],[Data Pattern (display name)]]="", "", VLOOKUP(Table2[[#This Row],[Data Pattern (display name)]],'dataType Data Pattern List'!A:B,2,FALSE)) -> REG_EX_HAN
A22: DT_INSTANCE_NAME | B22: STRING | C22: 1 | D22: 30 | E22: All Characters | F22: =IF(Table2[[#This Row],[Data Pattern (display name)]]="", "", VLOOKUP(Table2[[#This Row],[Data Pattern (display name)]],'dataType Data Pattern List'!A:B,2,FALSE)) -> REG_EX_ALL | G22: ○ | H22: ^[^'$%&\(\)=\^~,<>/\?]*$ | P22: except the following symbols: '$%&()=^~,<>/? | Q22: 一部記号（'$%&()=^~,<>/?）以外
A23: DT_APP_NAME | B23: STRING | C23: 1 | D23: 30 | E23: All Characters | F23: =IF(Table2[[#This Row],[Data Pattern (display name)]]="", "", VLOOKUP(Table2[[#This Row],[Data Pattern (display name)]],'dataType Data Pattern List'!A:B,2,FALSE)) -> REG_EX_ALL | G23: ○ | H23: ^[^'$%&\(\)=\^~,<>/\?]*$ | P23: except the following symbols: '$%&()=^~,<>/? | Q23: 一部記号（'$%&()=^~,<>/?）以外
A24: DT_WEB_PROTOCOL | B24: ENUM | F24: =IF(Table2[[#This Row],[Data Pattern (display name)]]="", "", VLOOKUP(Table2[[#This Row],[Data Pattern (display name)]],'dataType Data Pattern List'!A:B,2,FALSE)) | M24: 1
A25: DT_URL | B25: STRING | C25: 1 | D25: 100 | E25: Half-width | F25: =IF(Table2[[#This Row],[Data Pattern (display name)]]="", "", VLOOKUP(Table2[[#This Row],[Data Pattern (display name)]],'dataType Data Pattern List'!A:B,2,FALSE)) -> REG_EX_HAN | G25: ○ | H25: ^[a-zA-Z0-9 _@/=\-\.\?\&]*$ | P25: alphanumeric chars and symbols: (space)_@/=.?& | Q25: 半角英数と一部記号（(半角空白)_@/=.?&）
A26: DT_IP_ADDRESS | B26: STRING | C26: 7 | D26: 15 | E26: Half-width | F26: =IF(Table2[[#This Row],[Data Pattern (display name)]]="", "", VLOOKUP(Table2[[#This Row],[Data Pattern (display name)]],'dataType Data Pattern List'!A:B,2,FALSE)) -> REG_EX_HAN | G26: ○
A27: DT_MINUTES | B27: INTEGER | F27: =IF(Table2[[#This Row],[Data Pattern (display name)]]="", "", VLOOKUP(Table2[[#This Row],[Data Pattern (display name)]],'dataType Data Pattern List'!A:B,2,FALSE))
A28: DT_ACC_ROLE | B28: ENUM | F28: =IF(Table2[[#This Row],[Data Pattern (display name)]]="", "", VLOOKUP(Table2[[#This Row],[Data Pattern (display name)]],'dataType Data Pattern List'!A:B,2,FALSE)) | M28: 1
A29: DT_REMOTE_SERVER_KIND | B29: ENUM | F29: =IF(Table2[[#This Row],[Data Pattern (display name)]]="", "", VLOOKUP(Table2[[#This Row],[Data Pattern (display name)]],'dataType Data Pattern List'!A:B,2,FALSE)) | M29: 1
A30: DT_PORT | B30: INTEGER | F30: =IF(Table2[[#This Row],[Data Pattern (display name)]]="", "", VLOOKUP(Table2[[#This Row],[Data Pattern (display name)]],'dataType Data Pattern List'!A:B,2,FALSE))
A31: DT_FW_NAME | B31: STRING | C31: 1 | D31: 100 | E31: Half-width | F31: =IF(Table2[[#This Row],[Data Pattern (display name)]]="", "", VLOOKUP(Table2[[#This Row],[Data Pattern (display name)]],'dataType Data Pattern List'!A:B,2,FALSE)) -> REG_EX_HAN | G31: ○ | H31: ^[a-zA-Z0-9 _@/\-\.]*$ | P31: alphanumeric chars and symbols: (space)_@/-. | Q31: 半角英数と一部記号（(半角空白)_@/-.）
A32: DT_REGION | B32: STRING | C32: 1 | D32: 50 | E32: All Characters | F32: =IF(Table2[[#This Row],[Data Pattern (display name)]]="", "", VLOOKUP(Table2[[#This Row],[Data Pattern (display name)]],'dataType Data Pattern List'!A:B,2,FALSE)) -> REG_EX_ALL | G32: ○ | H32: ^[a-zA-Z0-9\-]*$ | P32: alphanumeric characters and '-' | Q32: 半角英数と「-」
A33: DT_DESC | B33: STRING | C33: 1 | D33: 100 | E33: All Characters | F33: =IF(Table2[[#This Row],[Data Pattern (display name)]]="", "", VLOOKUP(Table2[[#This Row],[Data Pattern (display name)]],'dataType Data Pattern List'!A:B,2,FALSE)) -> REG_EX_ALL | H33: ^[^'$%&\(\)=\^~,<>/\?]*$ | P33: except the following symbols: '$%&()=^~,<>/? | Q33: 一部記号（'$%&()=^~,<>/?）以外
A34: DT_MAIL_AUTH_KIND | B34: ENUM | F34: =IF(Table2[[#This Row],[Data Pattern (display name)]]="", "", VLOOKUP(Table2[[#This Row],[Data Pattern (display name)]],'dataType Data Pattern List'!A:B,2,FALSE)) | M34: 2
A35: DT_INTERVAL_TIME | B35: INTEGER | F35: =IF(Table2[[#This Row],[Data Pattern (display name)]]="", "", VLOOKUP(Table2[[#This Row],[Data Pattern (display name)]],'dataType Data Pattern List'!A:B,2,FALSE)) | I35: 3 | J35: 1440
A36: DT_QIITA_ITEM_ID | B36: STRING | C36: 20 | D36: 20 | E36: Half-width | F36: =IF(Table2[[#This Row],[Data Pattern (display name)]]="", "", VLOOKUP(Table2[[#This Row],[Data Pattern (display name)]],'dataType Data Pattern List'!A:B,2,FALSE)) -> REG_EX_HAN
A37: DT_QIITA_USER_ID | B37: STRING | C37: 1 | D37: 100 | E37: Half-width | F37: =IF(Table2[[#This Row],[Data Pattern (display name)]]="", "", VLOOKUP(Table2[[#This Row],[Data Pattern (display name)]],'dataType Data Pattern List'!A:B,2,FALSE)) -> REG_EX_HAN
A38: DT_QIITA_TITLE | B38: STRING | C38: 1 | D38: 255 | E38: All Characters | F38: =IF(Table2[[#This Row],[Data Pattern (display name)]]="", "", VLOOKUP(Table2[[#This Row],[Data Pattern (display name)]],'dataType Data Pattern List'!A:B,2,FALSE)) -> REG_EX_ALL | G38: ○
A39: DT_COUNT | B39: INTEGER | F39: =IF(Table2[[#This Row],[Data Pattern (display name)]]="", "", VLOOKUP(Table2[[#This Row],[Data Pattern (display name)]],'dataType Data Pattern List'!A:B,2,FALSE))
A40: DT_LONG_TEXT | B40: STRING | C40: 0 | D40: 65535 | E40: All Characters | F40: =IF(Table2[[#This Row],[Data Pattern (display name)]]="", "", VLOOKUP(Table2[[#This Row],[Data Pattern (display name)]],'dataType Data Pattern List'!A:B,2,FALSE)) -> REG_EX_ALL
A41: DT_QIITA_TAG_NAME | B41: STRING | C41: 1 | D41: 100 | E41: All Characters | F41: =IF(Table2[[#This Row],[Data Pattern (display name)]]="", "", VLOOKUP(Table2[[#This Row],[Data Pattern (display name)]],'dataType Data Pattern List'!A:B,2,FALSE)) -> REG_EX_ALL
...

Sheet Enum Definition
A1: Enum Definition
A3: * Enum class names are auto-generated from the DataType name. | F3: Default Language | G3: Additional Language 1 | H3: Additional Language 2 | I3: Additional Language 3
A4: Ex: DT_TRANSACTION_STATUS → Enum class name: TransactionStatusEnum | F4: =IF('General Settings'!$G$11=0,"",'General Settings'!$G$11) -> en | G4: =IF('General Settings'!$G$12=0,"",'General Settings'!$G$12) -> ja | H4: =IF('General Settings'!$G$13=0,"",'General Settings'!$G$13) | I4: =IF('General Settings'!$G$14=0,"",'General Settings'!$G$14)
A6: DataType Name | B6: code | C6: varName | D6: Java Only | E6: Notes | F6: Display Name (Default Lang) | G6: Display Name (Additional Lang 1) | H6: Display Name (Additional Lang 2) | I6: Display Name (Additional Lang 3)
A7: DT_ACC_ROLE | B7: 1 | C7: ACC_USER | F7: user | G7: ユーザ
A8: DT_ACC_ROLE | B8: 2 | C8: ACCOUNT_FULL_ACCESS | F8: group admin | G8: グループ管理者
A9: DT_ACC_ROLE | B9: 9 | C9: ADMIN_FULL_ACCESS | F9: system admin | G9: システム管理者
A10: DT_WEB_PROTOCOL | B10: 1 | C10: HTTP | F10: http | G10: http
A11: DT_WEB_PROTOCOL | B11: 2 | C11: HTTPS | F11: https | G11: https
A12: DT_CLOUD_SERVICE_KIND | B12: 01 | C12: AWS | F12: AWS | G12: AWS
A13: DT_CLOUD_SERVICE_KIND | B13: 11 | C13: WEB_ARENA_INDIGO | F13: WebARENA Indigo | G13: WebARENA Indigo
A14: DT_CLOUD_SERVICE_KIND | B14: 21 | C14: SAKURA_CLOUD | F14: sakura cloud | G14: さくらのクラウド
A15: DT_REMOTE_SERVER_KIND | B15: 1 | C15: HTTP_PROXY | F15: HTTP Proxy | G15: HTTP Proxy
A16: DT_REMOTE_SERVER_KIND | B16: 2 | C16: MONITORING | F16: MONITORING | G16: サーバ監視
A17: DT_MAIL_AUTH_KIND | B17: 01 | C17: ACC_NEW | F17: new account | G17: 新規アカウント
A18: DT_MAIL_AUTH_KIND | B18: 02 | C18: ACC_PASSWORD_RESET | F18: password reset | G18: パスワードリセット
A19: DT_MAIL_AUTH_KIND | B19: 03 | C19: ACC_MAIL_ADDRESS_CHANGED | F19: mail address changed | G19: メールアドレス変更

Sheet DB Item Definition
A1: DB Item Definition
AI2: Default Language | AJ2: Additional Language 1 | AK2: Additional Language 2 | AL2: Additional Language 3
AI3: =IF('General Settings'!$G$11=0,"",'General Settings'!$G$11) -> en | AJ3: =IF('General Settings'!$G$12=0,"",'General Settings'!$G$12) -> ja | AK3: =IF('General Settings'!$G$13=0,"",'General Settings'!$G$13) | AL3: =IF('General Settings'!$G$14=0,"",'General Settings'!$G$14)
A5: Table Name | B5: Column Name | C5: dataType | D5: dataType Check | E5: Java Only | F5: Surrogate key | G5: natural key (unique key) | H5: nullable | I5: Auto Numbering | J5: Force Numbering | K5: Auto Update | L5: Force Update | M5: Group Identifier | N5: Spring Audit | O5: Relation: Type | P5: Relation: Direction | Q5: Relation: Source Var Name | R5: Relation: Source Var itemNameKeyClass | S5: Relation: Target Table | T5: Relation: Target Column | U5: Relation: Target Var Name | V5: Relation: Target Var itemNameKeyClass | W5: Relation: Eager | X5: index1 | Y5: index2 | Z5: index3 | AA5: index4 | AB5: index5 | AC5: index6 | AD5: index7 | AE5: index8 | AF5: index9 | AG5: index10 | AH5: Notes | AI5: Column Display Name (Default Lang) | AJ5: Column Display Name (Additional Lang 1) | AK5: Column Display Name (Additional Lang 2) | AL5: Column Display Name (Additional Lang 3)
A6: ACC | B6: ID | C6: DT_SERIAL | D6: =IF(Table7[[#This Row],[dataType]]="","",IF(NOT(ISNA(VLOOKUP(Table7[[#This Row],[dataType]], 'dataType Definition'!A:A, 1,FALSE))), "○", "×")) -> ○ | F6: ○ | I6: ○ | M6: ○ | AI6: ID | AJ6: ID
A7: ACC | B7: MAIL_ADDRESS | C7: DT_MAIL_ADDRESS | D7: =IF(Table7[[#This Row],[dataType]]="","",IF(NOT(ISNA(VLOOKUP(Table7[[#This Row],[dataType]], 'dataType Definition'!A:A, 1,FALSE))), "○", "×")) -> ○ | G7: ○ | AI7: mail address | AJ7: メールアドレス
A8: ACC | B8: NAME | C8: DT_ACC_NAME | D8: =IF(Table7[[#This Row],[dataType]]="","",IF(NOT(ISNA(VLOOKUP(Table7[[#This Row],[dataType]], 'dataType Definition'!A:A, 1,FALSE))), "○", "×")) -> ○ | AI8: name | AJ8: アカウント名
A9: ACC | B9: IS_ADMIN | C9: DT_BOOL | D9: =IF(Table7[[#This Row],[dataType]]="","",IF(NOT(ISNA(VLOOKUP(Table7[[#This Row],[dataType]], 'dataType Definition'!A:A, 1,FALSE))), "○", "×")) -> ○ | AI9: is system administrator | AJ9: システム管理者
A10: ACC | B10: ROLE | C10: DT_ACC_ROLE | D10: =IF(Table7[[#This Row],[dataType]]="","",IF(NOT(ISNA(VLOOKUP(Table7[[#This Row],[dataType]], 'dataType Definition'!A:A, 1,FALSE))), "○", "×")) -> ○ | AI10: role | AJ10: ロール
A11: ACC | B11: HASHED_PASSWORD | C11: DT_HASHED_PASSWORD | D11: =IF(Table7[[#This Row],[dataType]]="","",IF(NOT(ISNA(VLOOKUP(Table7[[#This Row],[dataType]], 'dataType Definition'!A:A, 1,FALSE))), "○", "×")) -> ○ | H11: ○ | AI11: hashed password | AJ11: 暗号化済みパスワード
A12: ACC | B12: IS_VALID | C12: DT_BOOL | D12: =IF(Table7[[#This Row],[dataType]]="","",IF(NOT(ISNA(VLOOKUP(Table7[[#This Row],[dataType]], 'dataType Definition'!A:A, 1,FALSE))), "○", "×")) -> ○ | AI12: valid | AJ12: 有効
A13: ACC | B13: IS_AUTHENTICATED | C13: DT_BOOL | D13: =IF(Table7[[#This Row],[dataType]]="","",IF(NOT(ISNA(VLOOKUP(Table7[[#This Row],[dataType]], 'dataType Definition'!A:A, 1,FALSE))), "○", "×")) -> ○ | AI13: authenticated | AJ13: メール認証
A14: ACC | B14: HAS_LOGGED_IN | C14: DT_BOOL | D14: =IF(Table7[[#This Row],[dataType]]="","",IF(NOT(ISNA(VLOOKUP(Table7[[#This Row],[dataType]], 'dataType Definition'!A:A, 1,FALSE))), "○", "×")) -> ○ | AI14: has logged in | AJ14: ログイン実績あり
A15: ACC_ADMIN | B15: ACC_ID | C15: DT_SERIAL | D15: =IF(Table7[[#This Row],[dataType]]="","",IF(NOT(ISNA(VLOOKUP(Table7[[#This Row],[dataType]], 'dataType Definition'!A:A, 1,FALSE))), "○", "×")) -> ○ | F15: ○ | O15: @OneToOne | P15: bidirectional | Q15: acc | S15: ACC | T15: ID | U15: accAdmin | AI15: account ID | AJ15: アカウントID
A16: ACC_GENERAL | B16: ACC_ID | C16: DT_SERIAL | D16: =IF(Table7[[#This Row],[dataType]]="","",IF(NOT(ISNA(VLOOKUP(Table7[[#This Row],[dataType]], 'dataType Definition'!A:A, 1,FALSE))), "○", "×")) -> ○ | F16: ○ | O16: @OneToOne | P16: bidirectional | Q16: acc | S16: ACC | T16: ID | U16: accGeneral | AI16: account ID | AJ16: アカウントID
A17: ACC_GENERAL | B17: ACCESSIBLE_TO_ALL_APPS | C17: DT_BOOL | D17: =IF(Table7[[#This Row],[dataType]]="","",IF(NOT(ISNA(VLOOKUP(Table7[[#This Row],[dataType]], 'dataType Definition'!A:A, 1,FALSE))), "○", "×")) -> ○ | AI17: accessible to all apps | AJ17: 全サーバ・appアクセス可
A18: AGREEMENT | B18: ID | C18: DT_SERIAL | D18: =IF(Table7[[#This Row],[dataType]]="","",IF(NOT(ISNA(VLOOKUP(Table7[[#This Row],[dataType]], 'dataType Definition'!A:A, 1,FALSE))), "○", "×")) -> ○ | F18: ○ | I18: ○ | AI18: ID | AJ18: ID
A19: AGREEMENT | B19: UPLOADED_DATETIME | C19: DT_TIMESTAMP | D19: =IF(Table7[[#This Row],[dataType]]="","",IF(NOT(ISNA(VLOOKUP(Table7[[#This Row],[dataType]], 'dataType Definition'!A:A, 1,FALSE))), "○", "×")) -> ○ | AI19: uploaded datetime | AJ19: アップロード日時
A20: ACC_AGREEMENT | B20: ID | C20: DT_SERIAL | D20: =IF(Table7[[#This Row],[dataType]]="","",IF(NOT(ISNA(VLOOKUP(Table7[[#This Row],[dataType]], 'dataType Definition'!A:A, 1,FALSE))), "○", "×")) -> ○ | F20: ○ | I20: ○ | AI20: ID | AJ20: ID
A21: ACC_AGREEMENT | B21: ACC_ID | C21: DT_SERIAL | D21: =IF(Table7[[#This Row],[dataType]]="","",IF(NOT(ISNA(VLOOKUP(Table7[[#This Row],[dataType]], 'dataType Definition'!A:A, 1,FALSE))), "○", "×")) -> ○ | AI21: account ID | AJ21: アカウントID
A22: ACC_AGREEMENT | B22: AGREEMENT_ID | C22: DT_SERIAL | D22: =IF(Table7[[#This Row],[dataType]]="","",IF(NOT(ISNA(VLOOKUP(Table7[[#This Row],[dataType]], 'dataType Definition'!A:A, 1,FALSE))), "○", "×")) -> ○ | AI22: agreement version | AJ22: 利用規約バージョン
A23: MAIL_AUTH_MANAGEMENT | B23: ID | C23: DT_SERIAL | D23: =IF(Table7[[#This Row],[dataType]]="","",IF(NOT(ISNA(VLOOKUP(Table7[[#This Row],[dataType]], 'dataType Definition'!A:A, 1,FALSE))), "○", "×")) -> ○ | F23: ○ | I23: ○ | AI23: ID | AJ23: ID
A24: MAIL_AUTH_MANAGEMENT | B24: ACC_ID | C24: DT_SERIAL | D24: =IF(Table7[[#This Row],[dataType]]="","",IF(NOT(ISNA(VLOOKUP(Table7[[#This Row],[dataType]], 'dataType Definition'!A:A, 1,FALSE))), "○", "×")) -> ○ | AI24: account ID | AJ24: アカウントID
A25: MAIL_AUTH_MANAGEMENT | B25: AUTH_KIND | C25: DT_MAIL_AUTH_KIND | D25: =IF(Table7[[#This Row],[dataType]]="","",IF(NOT(ISNA(VLOOKUP(Table7[[#This Row],[dataType]], 'dataType Definition'!A:A, 1,FALSE))), "○", "×")) -> ○ | AI25: authentication kind | AJ25: 認証種別
A26: MAIL_AUTH_MANAGEMENT | B26: AUTH_CODE | C26: DT_CODE | D26: =IF(Table7[[#This Row],[dataType]]="","",IF(NOT(ISNA(VLOOKUP(Table7[[#This Row],[dataType]], 'dataType Definition'!A:A, 1,FALSE))), "○", "×")) -> ○ | AI26: authentication code | AJ26: 認証コード
A27: MAIL_AUTH_MANAGEMENT | B27: IS_VALID | C27: DT_BOOL | D27: =IF(Table7[[#This Row],[dataType]]="","",IF(NOT(ISNA(VLOOKUP(Table7[[#This Row],[dataType]], 'dataType Definition'!A:A, 1,FALSE))), "○", "×")) -> ○ | AI27: valid | AJ27: 有効
A28: MAIL_AUTH_MANAGEMENT | B28: HAS_USED | C28: DT_BOOL | D28: =IF(Table7[[#This Row],[dataType]]="","",IF(NOT(ISNA(VLOOKUP(Table7[[#This Row],[dataType]], 'dataType Definition'!A:A, 1,FALSE))), "○", "×")) -> ○ | AI28: used | AJ28: 使用済み
A29: MAIL_AUTH_MANAGEMENT | B29: NEW_MAIL_ADDRESS | C29: DT_MAIL_ADDRESS | D29: =IF(Table7[[#This Row],[dataType]]="","",IF(NOT(ISNA(VLOOKUP(Table7[[#This Row],[dataType]], 'dataType Definition'!A:A, 1,FALSE))), "○", "×")) -> ○ | H29: ○ | AI29: new mail address | AJ29: 変更後メールアドレス
A30: MAIL_AUTH_MANAGEMENT | B30: NEW_PASSWORD | C30: DT_HASHED_PASSWORD | D30: =IF(Table7[[#This Row],[dataType]]="","",IF(NOT(ISNA(VLOOKUP(Table7[[#This Row],[dataType]], 'dataType Definition'!A:A, 1,FALSE))), "○", "×")) -> ○ | H30: ○ | AI30: new password | AJ30: 変更後暗号化済みパスワード
A31: MAIL_AUTH_MANAGEMENT | B31: MAIL_SENT_DATETIME | C31: DT_TIMESTAMP | D31: =IF(Table7[[#This Row],[dataType]]="","",IF(NOT(ISNA(VLOOKUP(Table7[[#This Row],[dataType]], 'dataType Definition'!A:A, 1,FALSE))), "○", "×")) -> ○ | AI31: mail sent datetime | AJ31: メール送信日時
A32: QIITA_USER | B32: ID | C32: DT_SERIAL | D32: =IF(Table7[[#This Row],[dataType]]="","",IF(NOT(ISNA(VLOOKUP(Table7[[#This Row],[dataType]], 'dataType Definition'!A:A, 1,FALSE))), "○", "×")) -> ○ | F32: ○ | I32: ○ | AI32: ID | AJ32: ID
A33: QIITA_USER | B33: ACC_ID | C33: DT_SERIAL | D33: =IF(Table7[[#This Row],[dataType]]="","",IF(NOT(ISNA(VLOOKUP(Table7[[#This Row],[dataType]], 'dataType Definition'!A:A, 1,FALSE))), "○", "×")) -> ○ | O33: @ManyToOne | P33: unidirectional | Q33: acc | S33: ACC | T33: ID | AI33: account ID | AJ33: アカウントID
A34: QIITA_USER | B34: USER_ID_IN_QIITA_WEBSITE | C34: DT_QIITA_USER_ID | D34: =IF(Table7[[#This Row],[dataType]]="","",IF(NOT(ISNA(VLOOKUP(Table7[[#This Row],[dataType]], 'dataType Definition'!A:A, 1,FALSE))), "○", "×")) -> ○ | G34: ○ | AI34: Qiita user ID | AJ34: QiitaユーザーID
A35: QIITA_USER | B35: PERMANENT_ID | C35: DT_COUNT | D35: =IF(Table7[[#This Row],[dataType]]="","",IF(NOT(ISNA(VLOOKUP(Table7[[#This Row],[dataType]], 'dataType Definition'!A:A, 1,FALSE))), "○", "×")) -> ○ | AI35: permanent ID | AJ35: permanent ID
A36: QIITA_USER | B36: NAME | C36: DT_QIITA_TITLE | D36: =IF(Table7[[#This Row],[dataType]]="","",IF(NOT(ISNA(VLOOKUP(Table7[[#This Row],[dataType]], 'dataType Definition'!A:A, 1,FALSE))), "○", "×")) -> ○ | H36: ○ | AI36: name | AJ36: 表示名
A37: QIITA_USER | B37: DESCRIPTION | C37: DT_LONG_TEXT | D37: =IF(Table7[[#This Row],[dataType]]="","",IF(NOT(ISNA(VLOOKUP(Table7[[#This Row],[dataType]], 'dataType Definition'!A:A, 1,FALSE))), "○", "×")) -> ○ | H37: ○ | AI37: description | AJ37: 自己紹介
A38: QIITA_USER | B38: LOCATION | C38: DT_QIITA_TITLE | D38: =IF(Table7[[#This Row],[dataType]]="","",IF(NOT(ISNA(VLOOKUP(Table7[[#This Row],[dataType]], 'dataType Definition'!A:A, 1,FALSE))), "○", "×")) -> ○ | H38: ○ | AI38: location | AJ38: 居住地
A39: QIITA_USER | B39: ORGANIZATION | C39: DT_QIITA_TITLE | D39: =IF(Table7[[#This Row],[dataType]]="","",IF(NOT(ISNA(VLOOKUP(Table7[[#This Row],[dataType]], 'dataType Definition'!A:A, 1,FALSE))), "○", "×")) -> ○ | H39: ○ | AI39: organization | AJ39: 所属
A40: QIITA_USER | B40: FOLLOWEES_COUNT | C40: DT_COUNT | D40: =IF(Table7[[#This Row],[dataType]]="","",IF(NOT(ISNA(VLOOKUP(Table7[[#This Row],[dataType]], 'dataType Definition'!A:A, 1,FALSE))), "○", "×")) -> ○ | AI40: followees count | AJ40: フォロイー数
A41: QIITA_USER | B41: FOLLOWERS_COUNT | C41: DT_COUNT | D41: =IF(Table7[[#This Row],[dataType]]="","",IF(NOT(ISNA(VLOOKUP(Table7[[#This Row],[dataType]], 'dataType Definition'!A:A, 1,FALSE))), "○", "×")) -> ○ | AI41: followers count | AJ41: フォロワー数
...

Sheet DB Common Item Definition
A1: DB Common Item Definition
AI2: Default Language | AJ2: Additional Language 1 | AK2: Additional Language 2 | AL2: Additional Language 3
AI3: =IF('General Settings'!$G$11=0,"",'General Settings'!$G$11) -> en | AJ3: =IF('General Settings'!$G$12=0,"",'General Settings'!$G$12) -> ja | AK3: =IF('General Settings'!$G$13=0,"",'General Settings'!$G$13) | AL3: =IF('General Settings'!$G$14=0,"",'General Settings'!$G$14)
A5: Table Name | B5: Column Name | C5: dataType | D5: dataType Check | E5: Java Only | F5: Surrogate key | G5: natural key (unique key) | H5: nullable | I5: Auto Numbering | J5: Force Numbering | K5: Auto Update | L5: Force Update | M5: Group Identifier | N5: Spring Audit | O5: Relation: Type | P5: Relation: Direction | Q5: Relation: Source Var Name | R5: Relation: Source Var itemNameKeyClass | S5: Relation: Target Table | T5: Relation: Target Column | U5: Relation: Target Var Name | V5: Relation: Target Var itemNameKeyClass | W5: Relation: Eager | X5: index1 | Y5: index2 | Z5: index3 | AA5: index4 | AB5: index5 | AC5: index6 | AD5: index7 | AE5: index8 | AF5: index9 | AG5: index10 | AH5: Notes | AI5: Column Display Name (Default Lang) | AJ5: Column Display Name (Additional Lang 1) | AK5: Column Display Name (Additional Lang 2) | AL5: Column Display Name (Additional Lang 3)
B6: CREATE_ACC_ID | C6: DT_SERIAL | D6: =IF(Table74[[#This Row],[dataType]]="","",IF(NOT(ISNA(VLOOKUP(Table74[[#This Row],[dataType]], 'dataType Definition'!A:A, 1,FALSE))), "○", "×")) -> ○ | N6: CB | AI6: create account ID | AJ6: 作成者ID
B7: CREATE_ACC_NAME | C7: DT_ACC_NAME | D7: =IF(Table74[[#This Row],[dataType]]="","",IF(NOT(ISNA(VLOOKUP(Table74[[#This Row],[dataType]], 'dataType Definition'!A:A, 1,FALSE))), "○", "×")) -> ○ | E7: ○ | AI7: create account name | AJ7: 作成者名
B8: CREATE_TIME | C8: DT_TIMESTAMP | D8: =IF(Table74[[#This Row],[dataType]]="","",IF(NOT(ISNA(VLOOKUP(Table74[[#This Row],[dataType]], 'dataType Definition'!A:A, 1,FALSE))), "○", "×")) -> ○ | I8: ○ | J8: ○ | N8: CD | AI8: create time | AJ8: 作成日時
B9: LST_UPD_ACC_ID | C9: DT_SERIAL | D9: =IF(Table74[[#This Row],[dataType]]="","",IF(NOT(ISNA(VLOOKUP(Table74[[#This Row],[dataType]], 'dataType Definition'!A:A, 1,FALSE))), "○", "×")) -> ○ | N9: LB | AI9: last update account ID | AJ9: 最終更新者ID
B10: LST_UPD_ACC_NAME | C10: DT_ACC_NAME | D10: =IF(Table74[[#This Row],[dataType]]="","",IF(NOT(ISNA(VLOOKUP(Table74[[#This Row],[dataType]], 'dataType Definition'!A:A, 1,FALSE))), "○", "×")) -> ○ | E10: ○ | AI10: last update account name | AJ10: 最終更新者名
B11: LST_UPD_TIME | C11: DT_TIMESTAMP | D11: =IF(Table74[[#This Row],[dataType]]="","",IF(NOT(ISNA(VLOOKUP(Table74[[#This Row],[dataType]], 'dataType Definition'!A:A, 1,FALSE))), "○", "×")) -> ○ | I11: ○ | J11: ○ | K11: ○ | L11: ○ | N11: LD | AI11: last update time | AJ11: 最終更新日時
B12: DEL_FLG | C12: DT_BOOL | D12: =IF(Table74[[#This Row],[dataType]]="","",IF(NOT(ISNA(VLOOKUP(Table74[[#This Row],[dataType]], 'dataType Definition'!A:A, 1,FALSE))), "○", "×")) -> ○ | I12: ○ | AI12: delete flag | AJ12: 削除フラグ
B13: VERSION | C13: DT_DB_UPD_VER | D13: =IF(Table74[[#This Row],[dataType]]="","",IF(NOT(ISNA(VLOOKUP(Table74[[#This Row],[dataType]], 'dataType Definition'!A:A, 1,FALSE))), "○", "×")) -> ○ | AI13: version | AJ13: DB 更新バージョン
H29: ○
H30: ○
H36: ○
H37: ○
H38: ○
H39: ○
H43: ○
H44: ○
H45: ○
H46: ○
H47: ○
H48: ○
... H87: ○

Sheet Table List
A1: Table List
B2: Default Language | C2: Additional Language 1 | D2: Additional Language 2 | E2: Additional Language 3
B3: =IF('General Settings'!$G$11=0,"",'General Settings'!$G$11) -> en | C3: =IF('General Settings'!$G$12=0,"",'General Settings'!$G$12) -> ja | D3: =IF('General Settings'!$G$13=0,"",'General Settings'!$G$13) | E3: =IF('General Settings'!$G$14=0,"",'General Settings'!$G$14)
A5: Table Name | B5: Table Display Name (Default Lang) | C5: Table Display Name (Additional Lang 1) | D5: Table Display Name (Additional Lang 2) | E5: Table Display Name (Additional Lang 3)
A6: {=_xlfn.UNIQUE(_xlfn._xlws.FILTER(Table7[Table Name], Table7[Table Name]<>""))} -> ACC | B6: account | C6: アカウント
A7: ACC_ADMIN | B7: administrator account | C7: 管理者アカウント
A8: ACC_GENERAL | B8: general account | C8: 一般アカウント
A9: AGREEMENT | B9: agreement | C9: 利用規約
A10: ACC_AGREEMENT | B10: account - agreement | C10: アカウント・利用規約
A11: MAIL_AUTH_MANAGEMENT | B11: mail authentication manageement | C11: メール認証管理
A12: QIITA_USER | B12: qiita user | C12: qiita user
A13: QIITA_GROUP | B13: qiita group | C13: qiita group
A14: QIITA_ITEM | B14: qiita item | C14: qiita item
A15: QIITA_TAG | B15: qiita tag | C15: qiita tag
A16: QIITA_ITEM_TAG | B16: qiita item tag | C16: qiita item tag
A17: QIITA_ITEM_TAG_VERSION | B17: qiita iitem tag version | C17: qiita iitem tag version
